Workbook

Sheet Sheet3
A3: Row Labels
A4: Actitis macularius
A5: Amazilia tzacatl
A6: Amazona autumnalis
A7: Amazona farinosa
A8: Anthracothorax nigricollis
A9: Ardea alba
A10: Arremon aurantiirostris
A11: Attila spadiceus
A12: Baryphthengus martii
A13: Buteogallus anthracinus
A14: Buteogallus urubitinga
... A140: Grand Total

Sheet Sheet4
A1: especie | B1: Manacus
A2: Tinamus major | B2: =VLOOKUP(A2,manacus!$C$1:$D$1034,2,FALSE) -> Great Tinamou
A3: Crypturellus soui | B3: =VLOOKUP(A3,manacus!$C$1:$D$1034,2,FALSE) -> Little Tinamou
A4: Crypturellus kerriae | B4: =VLOOKUP(A4,manacus!$C$1:$D$1034,2,FALSE) -> Choco Tinamou
A5: Penelope purpurascens | B5: =VLOOKUP(A5,manacus!$C$1:$D$1034,2,FALSE) -> Crested Guan
A6: Crax rubra | B6: =VLOOKUP(A6,manacus!$C$1:$D$1034,2,FALSE) -> Great Curassow
A7: Rhynchortyx cinctus | B7: =VLOOKUP(A7,manacus!$C$1:$D$1034,2,FALSE) -> #N/A
A8: Patagioenas cayennensis | B8: =VLOOKUP(A8,manacus!$C$1:$D$1034,2,FALSE) -> #N/A
A9: Patagioenas speciosa | B9: =VLOOKUP(A9,manacus!$C$1:$D$1034,2,FALSE) -> #N/A
A10: Patagioenas plumbea | B10: =VLOOKUP(A10,manacus!$C$1:$D$1034,2,FALSE) -> #N/A
A11: Patagioenas goodsoni | B11: =VLOOKUP(A11,manacus!$C$1:$D$1034,2,FALSE) -> Dusky Pigeon
A12: Columbina talpacoti | B12: =VLOOKUP(A12,manacus!$C$1:$D$1034,2,FALSE) -> #N/A
A13: Leptotila verreauxi | B13: =VLOOKUP(A13,manacus!$C$1:$D$1034,2,FALSE) -> #N/A
... A137: Saltator maximus | B137: =VLOOKUP(A137,manacus!$C$1:$D$1034,2,FALSE) -> Buff-throated Saltator

Sheet manacus
A1: tax_order | B1: category | C1: sci_name | D1: comm_name | E1: exotic | F1: count | G1: country | H1: state | I1: lat | J1: lon | K1: dates | L1: observer | M1: media | N1: gui | O1: comments
A2: 10310 | B2: species | C2: Capito maculicoronatus | D2: Spot-crowned Barbet | F2: 3 | G2: Colombia | H2: Choc√≥ | I2: 5.6008 | J2: -77.44218 | K2: 44757 | L2: obsr169881 | M2: 1 | N2: URN:CornellLabOfOrnithology:EBIRD:OBS1480692950 | O2: Manacus2022_Manacus expedition LSU-Humboldt Institute 2022. After setting up nets. With Salma, Mori, and Callito.
A3: 10407 | B3: species | C3: Pteroglossus torquatus | D3: Collared Aracari | F3: 1 | G3: Colombia | H3: Choc√≥ | I3: 5.6008 | J3: -77.44218 | K3: 44756 | L3: obsr169881 | M3: 0 | N3: URN:CornellLabOfOrnithology:EBIRD:OBS1480697007 | O3: Manacus2022_Manacus expedition LSU-Humboldt Institute 2022. Con Sebastian en la finca de Salma.
A4: 10407 | B4: species | C4: Pteroglossus torquatus | D4: Collared Aracari | F4: 1 | G4: Colombia | H4: Choc√≥ | I4: 5.6008 | J4: -77.44218 | K4: 44756 | L4: obsr792981 | M4: 0 | N4: URN:CornellLabOfOrnithology:EBIRD:OBS1504401832
A5: 10407 | B5: species | C5: Pteroglossus torquatus | D5: Collared Aracari | F5: 1 | G5: Colombia | H5: Choc√≥ | I5: 5.603758 | J5: -77.437378 | K5: 44759 | L5: obsr169881 | M5: 0 | N5: URN:CornellLabOfOrnithology:EBIRD:OBS1481741353 | O5: Manacus2022_Manacus expedition LSU-Humboldt Institute 2022. Sendero cuatro encantos. After setting up nets by Phaethornis lek. With Salma. Stopped along trail for breakfast at 930. Walking very slow, doing playback for various species. Recording. Joined at end by Diego, Valentina, Mori, and Callito (Diego had his own list running). Started at nets, walked up trail, ended count back at nets.
A6: 10407 | B6: species | C6: Pteroglossus torquatus | D6: Collared Aracari | F6: 4 | G6: Colombia | H6: Choc√≥ | I6: 5.616211 | J6: -77.429894 | K6: 44758 | L6: obsr169881 | M6: 0 | N6: URN:CornellLabOfOrnithology:EBIRD:OBS1486652588 | O6: Manacus2022_Manacus expedition LSU-Humboldt Institute 2022.
A7: 10407 | B7: species | C7: Pteroglossus torquatus | D7: Collared Aracari | F7: 4 | G7: Colombia | H7: Choc√≥ | I7: 5.616211 | J7: -77.429894 | K7: 44758 | L7: obsr436508 | M7: 0 | N7: URN:CornellLabOfOrnithology:EBIRD:OBS1480640791 | O7: Manacus2022_
A8: 10446 | B8: species | C8: Ramphastos ambiguus | D8: Yellow-throated Toucan | F8: 1 | G8: Colombia | H8: Choc√≥ | I8: 5.574783 | J8: -77.495739 | K8: 44762 | L8: obsr169881 | M8: 0 | N8: URN:CornellLabOfOrnithology:EBIRD:OBS1483079698 | O8: Manacus2022_Manacus expedition LSU-Humboldt Institute 2022. FYI had one earlier observation this morning: an incidental on hike out to nets on Camino to Rio Arusisito. It was a recording of a high pitched song. Started current list at far nets on Camino to Rio Arusisito. With Sammy as guide. Stopped list when torrential rain started.
A9: 10446 | B9: species | C9: Ramphastos ambiguus | D9: Yellow-throated Toucan | F9: 1 | G9: Colombia | H9: Choc√≥ | I9: 5.598741 | J9: -77.445042 | K9: 44755 | L9: obsr792981 | M9: 0 | N9: URN:CornellLabOfOrnithology:EBIRD:OBS1485332565
A10: 10446 | B10: species | C10: Ramphastos ambiguus | D10: Yellow-throated Toucan | F10: 1 | G10: Colombia | H10: Choc√≥ | I10: 5.6026791 | J10: -77.442741 | K10: 44755 | L10: obsr792981 | M10: 0 | N10: URN:CornellLabOfOrnithology:EBIRD:OBS1485333094
A11: 10446 | B11: species | C11: Ramphastos ambiguus | D11: Yellow-throated Toucan | F11: 1 | G11: Colombia | H11: Choc√≥ | I11: 5.6033574 | J11: -77.435157 | K11: 44759 | L11: obsr436508 | M11: 0 | N11: URN:CornellLabOfOrnithology:EBIRD:OBS1481750891 | O11: Manacus2022_
A12: 10446 | B12: species | C12: Ramphastos ambiguus | D12: Yellow-throated Toucan | F12: 1 | G12: Colombia | H12: Choc√≥ | I12: 5.603758 | J12: -77.437378 | K12: 44759 | L12: obsr169881 | M12: 0 | N12: URN:CornellLabOfOrnithology:EBIRD:OBS1481741360 | O12: Manacus2022_Manacus expedition LSU-Humboldt Institute 2022. Sendero cuatro encantos. After setting up nets by Phaethornis lek. With Salma. Stopped along trail for breakfast at 930. Walking very slow, doing playback for various species. Recording. Joined at end by Diego, Valentina, Mori, and Callito (Diego had his own list running). Started at nets, walked up trail, ended count back at nets.
A13: 10446 | B13: species | C13: Ramphastos ambiguus | D13: Yellow-throated Toucan | F13: 2 | G13: Colombia | H13: Choc√≥ | I13: 5.5712682 | J13: -77.501856 | K13: 44761 | L13: obsr436508 | M13: 0 | N13: URN:CornellLabOfOrnithology:EBIRD:OBS1498845104 | O13: Manacus2022_
A14: 10446 | B14: species | C14: Ramphastos ambiguus | D14: Yellow-throated Toucan | F14: 2 | G14: Colombia | H14: Choc√≥ | I14: 5.572016 | J14: -77.498527 | K14: 44760 | L14: obsr169881 | M14: 0 | N14: URN:CornellLabOfOrnithology:EBIRD:OBS1481970787 | O14: Manacus2022_Manacus expedition LSU-Humboldt Institute 2022. El Amargal: camino hasta cuchilla de Arus√≠. With Armancio as guide. Light rain and super quiet overall. After walking up the trail a few hundred meters we turned back and I ended the list a little short of the El Amargal buildings when it was getting dark.
A15: 10446 | B15: species | C15: Ramphastos ambiguus | D15: Yellow-throated Toucan | F15: 2 | G15: Colombia | H15: Choc√≥ | I15: 5.5747881 | J15: -77.498199 | K15: 44761 | L15: obsr792981 | M15: 0 | N15: URN:CornellLabOfOrnithology:EBIRD:OBS1484895809
A16: 10446 | B16: species | C16: Ramphastos ambiguus | D16: Yellow-throated Toucan | F16: 2 | G16: Colombia | H16: Choc√≥ | I16: 5.6033574 | J16: -77.435157 | K16: 44388 | L16: obsr436508 | M16: 0 | N16: URN:CornellLabOfOrnithology:EBIRD:OBS1199322243
A17: 10446 | B17: species | C17: Ramphastos ambiguus | D17: Yellow-throated Toucan | F17: 2 | G17: Colombia | H17: Choc√≥ | I17: 5.603758 | J17: -77.437378 | K17: 44754 | L17: obsr169881 | M17: 0 | N17: URN:CornellLabOfOrnithology:EBIRD:OBS1480702458 | O17: Manacus2022_Manacus expedition LSU-Humboldt Institute 2022. Walked east from the town of Termales, reached the "termales spa del pacifico", and then took the Camino Cuatro Encantos. We walked only a few hundred meters along the camino and then turned back. Scouting for Manacus. With Sebastian, Maira, and guides. Ebird track for this list is WAY off due to user error--accidentally continued a list from a previous site. Have since fixed error, except for lingering eBird track.
A18: 10446 | B18: species | C18: Ramphastos ambiguus | D18: Yellow-throated Toucan | F18: 2 | G18: Colombia | H18: Choc√≥ | I18: 5.603758 | J18: -77.437378 | K18: 44754 | L18: obsr792981 | M18: 0 | N18: URN:CornellLabOfOrnithology:EBIRD:OBS1497532072
A19: 10446 | B19: species | C19: Ramphastos ambiguus | D19: Yellow-throated Toucan | F19: 2 | G19: Colombia | H19: Choc√≥ | I19: 5.6121815 | J19: -77.434699 | K19: 44759 | L19: obsr792981 | M19: 0 | N19: URN:CornellLabOfOrnithology:EBIRD:OBS1485333058
A20: 10446 | B20: species | C20: Ramphastos ambiguus | D20: Yellow-throated Toucan | F20: 2 | G20: Colombia | H20: Choc√≥ | I20: 5.614659 | J20: -77.424991 | K20: 44758 | L20: obsr169881 | M20: 0 | N20: URN:CornellLabOfOrnithology:EBIRD:OBS1504613188 | O20: Manacus2022_
A21: 10446 | B21: species | C21: Ramphastos ambiguus | D21: Yellow-throated Toucan | F21: 2 | G21: Colombia | H21: Choc√≥ | I21: 5.614659 | J21: -77.424991 | K21: 44758 | L21: obsr436508 | M21: 0 | N21: URN:CornellLabOfOrnithology:EBIRD:OBS1480643163 | O21: Manacus2022_
A22: 10446 | B22: species | C22: Ramphastos ambiguus | D22: Yellow-throated Toucan | F22: 2 | G22: Colombia | H22: Choc√≥ | I22: 5.616211 | J22: -77.429894 | K22: 44757 | L22: obsr436508 | M22: 0 | N22: URN:CornellLabOfOrnithology:EBIRD:OBS1480636746 | O22: Manacus2022_
A23: 10446 | B23: species | C23: Ramphastos ambiguus | D23: Yellow-throated Toucan | F23: 3 | G23: Colombia | H23: Choc√≥ | I23: 5.5747497 | J23: -77.498879 | K23: 44760 | L23: obsr792981 | M23: 0 | N23: URN:CornellLabOfOrnithology:EBIRD:OBS1484890072
A24: 10446 | B24: species | C24: Ramphastos ambiguus | D24: Yellow-throated Toucan | F24: 3 | G24: Colombia | H24: Choc√≥ | I24: 5.5996931 | J24: -77.443468 | K24: 44758 | L24: obsr792981 | M24: 0 | N24: URN:CornellLabOfOrnithology:EBIRD:OBS1480701377
A25: 10446 | B25: species | C25: Ramphastos ambiguus | D25: Yellow-throated Toucan | F25: 3 | G25: Colombia | H25: Choc√≥ | I25: 5.6121815 | J25: -77.434699 | K25: 44759 | L25: obsr792981 | M25: 0 | N25: URN:CornellLabOfOrnithology:EBIRD:OBS1484895946
A26: 10446 | B26: species | C26: Ramphastos ambiguus | D26: Yellow-throated Toucan | F26: 4 | G26: Colombia | H26: Choc√≥ | I26: 5.5748063 | J26: -77.497723 | K26: 44761 | L26: obsr792981 | M26: 0 | N26: URN:CornellLabOfOrnithology:EBIRD:OBS1484896705
A27: 10446 | B27: species | C27: Ramphastos ambiguus | D27: Yellow-throated Toucan | F27: 4 | G27: Colombia | H27: Choc√≥ | I27: 5.5998188 | J27: -77.44438 | K27: 44757 | L27: obsr792981 | M27: 0 | N27: URN:CornellLabOfOrnithology:EBIRD:OBS1480688702
A28: 10446 | B28: species | C28: Ramphastos ambiguus | D28: Yellow-throated Toucan | F28: 6 | G28: Colombia | H28: Choc√≥ | I28: 5.6008 | J28: -77.44218 | K28: 44757 | L28: obsr169881 | M28: 1 | N28: URN:CornellLabOfOrnithology:EBIRD:OBS1480692952 | O28: Manacus2022_Manacus expedition LSU-Humboldt Institute 2022. After setting up nets. With Salma, Mori, and Callito.
A29: 10446 | B29: species | C29: Ramphastos ambiguus | D29: Yellow-throated Toucan | F29: 6 | G29: Colombia | H29: Choc√≥ | I29: 5.615531 | J29: -77.428772 | K29: 44755 | L29: obsr169881 | M29: 0 | N29: URN:CornellLabOfOrnithology:EBIRD:OBS1486652531 | O29: Manacus2022_Manacus expedition LSU-Humboldt Institute 2022. Valeria and Glenn woke at 4 and hiked down beach to meet Andre at Termales. We then walked down path towards Playa Terco and met our guide Guere Guere at his house. A colorful older gentleman from Bogota [AEM edit: from Medellin I think] and former world traveler living a bit of a retired pirate‚Äôs life. Walked down beach and took a side path to reach Quebrada El Terco. A gentle, sandy stream through excellent forest. Shallow enough for boots for the most part. Where the valley narrowed we took a side trail up to a ridge that connected with the trails of El Cantil lodge and explored a bit up there. We returned to the steam around 10 and walked a short ways further up the stream to an impressive cascade with a small pool for swimming. Guere Guere went in his birthday suit; Andre, Valeria, y yo were a bit more modest.
A30: 10446 | B30: species | C30: Ramphastos ambiguus | D30: Yellow-throated Toucan | F30: 7 | G30: Colombia | H30: Choc√≥ | I30: 5.616211 | J30: -77.429894 | K30: 44758 | L30: obsr169881 | M30: 0 | N30: URN:CornellLabOfOrnithology:EBIRD:OBS1486652581 | O30: Manacus2022_Manacus expedition LSU-Humboldt Institute 2022.
A31: 10446 | B31: species | C31: Ramphastos ambiguus | D31: Yellow-throated Toucan | F31: 7 | G31: Colombia | H31: Choc√≥ | I31: 5.616211 | J31: -77.429894 | K31: 44758 | L31: obsr436508 | M31: 0 | N31: URN:CornellLabOfOrnithology:EBIRD:OBS1480640784 | O31: Manacus2022_
A32: 10459 | B32: species | C32: Ramphastos brevis | D32: Choco Toucan | F32: 1 | G32: Colombia | H32: Choc√≥ | I32: 5.570735 | J32: -77.497034 | K32: 44762 | L32: obsr436508 | M32: 0 | N32: URN:CornellLabOfOrnithology:EBIRD:OBS1498853137 | O32: Manacus2022_
A33: 10459 | B33: species | C33: Ramphastos brevis | D33: Choco Toucan | F33: 1 | G33: Colombia | H33: Choc√≥ | I33: 5.572016 | J33: -77.498527 | K33: 44761 | L33: obsr169881 | M33: 1 | N33: URN:CornellLabOfOrnithology:EBIRD:OBS1482382050 | O33: Manacus2022_Manacus expedition LSU-Humboldt Institute 2022. With Armancio as guide, we started at the El Amargal clearing then walked the Camino hasta Cuchilla de Arus√≠. Ending at clearing near the cuchilla (ridgetop) where we ate breakfast and hung out for a while. Good lighting and open views there for some canopy birds.
A34: 10459 | B34: species | C34: Ramphastos brevis | D34: Choco Toucan | F34: 1 | G34: Colombia | H34: Choc√≥ | I34: 5.5748063 | J34: -77.497723 | K34: 44761 | L34: obsr792981 | M34: 0 | N34: URN:CornellLabOfOrnithology:EBIRD:OBS1484896714
A35: 10459 | B35: species | C35: Ramphastos brevis | D35: Choco Toucan | F35: 1 | G35: Colombia | H35: Choc√≥ | I35: 5.598741 | J35: -77.445042 | K35: 44756 | L35: obsr436508 | M35: 0 | N35: URN:CornellLabOfOrnithology:EBIRD:OBS1480647490 | O35: Manacus2022_
A36: 10459 | B36: species | C36: Ramphastos brevis | D36: Choco Toucan | F36: 1 | G36: Colombia | H36: Choc√≥ | I36: 5.603758 | J36: -77.437378 | K36: 44759 | L36: obsr169881 | M36: 0 | N36: URN:CornellLabOfOrnithology:EBIRD:OBS1481741363 | O36: Manacus2022_Manacus expedition LSU-Humboldt Institute 2022. Sendero cuatro encantos. After setting up nets by Phaethornis lek. With Salma. Stopped along trail for breakfast at 930. Walking very slow, doing playback for various species. Recording. Joined at end by Diego, Valentina, Mori, and Callito (Diego had his own list running). Started at nets, walked up trail, ended count back at nets.
A37: 10459 | B37: species | C37: Ramphastos brevis | D37: Choco Toucan | F37: 2 | G37: Colombia | H37: Choc√≥ | I37: 5.5712682 | J37: -77.501856 | K37: 44761 | L37: obsr436508 | M37: 0 | N37: URN:CornellLabOfOrnithology:EBIRD:OBS1498845119 | O37: Manacus2022_
A38: 10459 | B38: species | C38: Ramphastos brevis | D38: Choco Toucan | F38: 2 | G38: Colombia | H38: Choc√≥ | I38: 5.5729971 | J38: -77.498555 | K38: 44762 | L38: obsr792981 | M38: 0 | N38: URN:CornellLabOfOrnithology:EBIRD:OBS1484893433
A39: 10459 | B39: species | C39: Ramphastos brevis | D39: Choco Toucan | F39: 2 | G39: Colombia | H39: Choc√≥ | I39: 5.574783 | J39: -77.495739 | K39: 44762 | L39: obsr169881 | M39: 0 | N39: URN:CornellLabOfOrnithology:EBIRD:OBS1483079690 | O39: Manacus2022_Manacus expedition LSU-Humboldt Institute 2022. FYI had one earlier observation this morning: an incidental on hike out to nets on Camino to Rio Arusisito. It was a recording of a high pitched song. Started current list at far nets on Camino to Rio Arusisito. With Sammy as guide. Stopped list when torrential rain started.
A40: 10459 | B40: species | C40: Ramphastos brevis | D40: Choco Toucan | F40: 2 | G40: Colombia | H40: Choc√≥ | I40: 5.6121815 | J40: -77.434699 | K40: 44759 | L40: obsr792981 | M40: 0 | N40: URN:CornellLabOfOrnithology:EBIRD:OBS1485333060
...

Sheet Termales
A1: sci_name | B1: tax_order | C1: category | D1: comm_name | E1: exotic | F1: count | G1: country | H1: state | I1: lat | J1: lon | K1: dates | L1: observer | M1: media | N1: gui | O1: comments
A2: Capito maculicoronatus | B2: 10310 | C2: species | D2: Spot-crowned Barbet | F2: X | G2: Colombia | H2: Choc√≥ | I2: 5.5729759 | J2: -77.502419 | K2: 44622 | L2: obsr161341 | M2: 0 | N2: URN:CornellLabOfOrnithology:EBIRD:OBS1360118838 | O2: Birds seen/heard during March 2 ‚Äì 6, 2002 at El Amargal. Birding was not the primary activity in this visit. Lots of rain and cloudy days.
A3: Pteroglossus torquatus | B3: 10407 | C3: species | D3: Collared Aracari | F3: X | G3: Colombia | H3: Choc√≥ | I3: 5.5729759 | J3: -77.502419 | K3: 44622 | L3: obsr161341 | M3: 0 | N3: URN:CornellLabOfOrnithology:EBIRD:OBS1360123133 | O3: Birds seen/heard during March 2 ‚Äì 6, 2002 at El Amargal. Birding was not the primary activity in this visit. Lots of rain and cloudy days.
A4: Ramphastos ambiguus | B4: 10446 | C4: species | D4: Yellow-throated Toucan | F4: 1 | G4: Colombia | H4: Choc√≥ | I4: 5.574783 | J4: -77.495739 | K4: 44762 | L4: obsr169881 | M4: 0 | N4: URN:CornellLabOfOrnithology:EBIRD:OBS1483079698 | O4: Manacus2022_Manacus expedition LSU-Humboldt Institute 2022. FYI had one earlier observation this morning: an incidental on hike out to nets on Camino to Rio Arusisito. It was a recording of a high pitched song. Started current list at far nets on Camino to Rio Arusisito. With Sammy as guide. Stopped list when torrential rain started.
A5: Ramphastos ambiguus | B5: 10446 | C5: species | D5: Yellow-throated Toucan | F5: 2 | G5: Colombia | H5: Choc√≥ | I5: 5.5712682 | J5: -77.501856 | K5: 44761 | L5: obsr436508 | M5: 0 | N5: URN:CornellLabOfOrnithology:EBIRD:OBS1498845104 | O5: Manacus2022_
A6: Ramphastos ambiguus | B6: 10446 | C6: species | D6: Yellow-throated Toucan | F6: 2 | G6: Colombia | H6: Choc√≥ | I6: 5.5712682 | J6: -77.501856 | K6: 44761 | L6: obsr803013 | M6: 0 | N6: URN:CornellLabOfOrnithology:EBIRD:OBS1485273560
A7: Ramphastos ambiguus | B7: 10446 | C7: species | D7: Yellow-throated Toucan | F7: 2 | G7: Colombia | H7: Choc√≥ | I7: 5.572016 | J7: -77.498527 | K7: 44760 | L7: obsr169881 | M7: 0 | N7: URN:CornellLabOfOrnithology:EBIRD:OBS1481970787 | O7: Manacus2022_Manacus expedition LSU-Humboldt Institute 2022. El Amargal: camino hasta cuchilla de Arus√≠. With Armancio as guide. Light rain and super quiet overall. After walking up the trail a few hundred meters we turned back and I ended the list a little short of the El Amargal buildings when it was getting dark.
A8: Ramphastos ambiguus | B8: 10446 | C8: species | D8: Yellow-throated Toucan | F8: 2 | G8: Colombia | H8: Choc√≥ | I8: 5.5747881 | J8: -77.498199 | K8: 44761 | L8: obsr792981 | M8: 0 | N8: URN:CornellLabOfOrnithology:EBIRD:OBS1484895809
A9: Ramphastos ambiguus | B9: 10446 | C9: species | D9: Yellow-throated Toucan | F9: 3 | G9: Colombia | H9: Choc√≥ | I9: 5.5747497 | J9: -77.498879 | K9: 44760 | L9: obsr792981 | M9: 0 | N9: URN:CornellLabOfOrnithology:EBIRD:OBS1484890072
A10: Ramphastos ambiguus | B10: 10446 | C10: species | D10: Yellow-throated Toucan | F10: 3 | G10: Colombia | H10: Choc√≥ | I10: 5.5747497 | J10: -77.498879 | K10: 44760 | L10: obsr803013 | M10: 0 | N10: URN:CornellLabOfOrnithology:EBIRD:OBS1485242246
A11: Ramphastos ambiguus | B11: 10446 | C11: species | D11: Yellow-throated Toucan | F11: 4 | G11: Colombia | H11: Choc√≥ | I11: 5.5748063 | J11: -77.497723 | K11: 44761 | L11: obsr792981 | M11: 0 | N11: URN:CornellLabOfOrnithology:EBIRD:OBS1484896705
A12: Ramphastos ambiguus | B12: 10446 | C12: species | D12: Yellow-throated Toucan | F12: X | G12: Colombia | H12: Choc√≥ | I12: 5.5729759 | J12: -77.502419 | K12: 44622 | L12: obsr161341 | M12: 0 | N12: URN:CornellLabOfOrnithology:EBIRD:OBS1360123131 | O12: Birds seen/heard during March 2 ‚Äì 6, 2002 at El Amargal. Birding was not the primary activity in this visit. Lots of rain and cloudy days.
A13: Ramphastos ambiguus | B13: 10446 | C13: species | D13: Yellow-throated Toucan | F13: X | G13: Colombia | H13: Choc√≥ | I13: 5.5781014 | J13: -77.502601 | K13: 42029 | L13: obsr399671 | M13: 0 | N13: URN:CornellLabOfOrnithology:EBIRD:OBS294630821
A14: Ramphastos brevis | B14: 10459 | C14: species | D14: Choco Toucan | F14: 1 | G14: Colombia | H14: Choc√≥ | I14: 5.570735 | J14: -77.497034 | K14: 44762 | L14: obsr436508 | M14: 0 | N14: URN:CornellLabOfOrnithology:EBIRD:OBS1498853137 | O14: Manacus2022_
A15: Ramphastos brevis | B15: 10459 | C15: species | D15: Choco Toucan | F15: 1 | G15: Colombia | H15: Choc√≥ | I15: 5.570735 | J15: -77.497034 | K15: 44762 | L15: obsr803013 | M15: 0 | N15: URN:CornellLabOfOrnithology:EBIRD:OBS1485279860
A16: Ramphastos brevis | B16: 10459 | C16: species | D16: Choco Toucan | F16: 1 | G16: Colombia | H16: Choc√≥ | I16: 5.572016 | J16: -77.498527 | K16: 44761 | L16: obsr169881 | M16: 1 | N16: URN:CornellLabOfOrnithology:EBIRD:OBS1482382050 | O16: Manacus2022_Manacus expedition LSU-Humboldt Institute 2022. With Armancio as guide, we started at the El Amargal clearing then walked the Camino hasta Cuchilla de Arus√≠. Ending at clearing near the cuchilla (ridgetop) where we ate breakfast and hung out for a while. Good lighting and open views there for some canopy birds.
A17: Ramphastos brevis | B17: 10459 | C17: species | D17: Choco Toucan | F17: 1 | G17: Colombia | H17: Choc√≥ | I17: 5.5748063 | J17: -77.497723 | K17: 44761 | L17: obsr792981 | M17: 0 | N17: URN:CornellLabOfOrnithology:EBIRD:OBS1484896714
A18: Ramphastos brevis | B18: 10459 | C18: species | D18: Choco Toucan | F18: 2 | G18: Colombia | H18: Choc√≥ | I18: 5.5712682 | J18: -77.501856 | K18: 44761 | L18: obsr436508 | M18: 0 | N18: URN:CornellLabOfOrnithology:EBIRD:OBS1498845119 | O18: Manacus2022_
A19: Ramphastos brevis | B19: 10459 | C19: species | D19: Choco Toucan | F19: 2 | G19: Colombia | H19: Choc√≥ | I19: 5.5712682 | J19: -77.501856 | K19: 44761 | L19: obsr803013 | M19: 0 | N19: URN:CornellLabOfOrnithology:EBIRD:OBS1485273575
A20: Ramphastos brevis | B20: 10459 | C20: species | D20: Choco Toucan | F20: 2 | G20: Colombia | H20: Choc√≥ | I20: 5.5729971 | J20: -77.498555 | K20: 44762 | L20: obsr792981 | M20: 0 | N20: URN:CornellLabOfOrnithology:EBIRD:OBS1484893433
A21: Ramphastos brevis | B21: 10459 | C21: species | D21: Choco Toucan | F21: 2 | G21: Colombia | H21: Choc√≥ | I21: 5.574783 | J21: -77.495739 | K21: 44762 | L21: obsr169881 | M21: 0 | N21: URN:CornellLabOfOrnithology:EBIRD:OBS1483079690 | O21: Manacus2022_Manacus expedition LSU-Humboldt Institute 2022. FYI had one earlier observation this morning: an incidental on hike out to nets on Camino to Rio Arusisito. It was a recording of a high pitched song. Started current list at far nets on Camino to Rio Arusisito. With Sammy as guide. Stopped list when torrential rain started.
A22: Ramphastos brevis | B22: 10459 | C22: species | D22: Choco Toucan | F22: X | G22: Colombia | H22: Choc√≥ | I22: 5.5729759 | J22: -77.502419 | K22: 44622 | L22: obsr161341 | M22: 0 | N22: URN:CornellLabOfOrnithology:EBIRD:OBS1360123138 | O22: Birds seen/heard during March 2 ‚Äì 6, 2002 at El Amargal. Birding was not the primary activity in this visit. Lots of rain and cloudy days.
A23: Ramphastos brevis | B23: 10459 | C23: species | D23: Choco Toucan | F23: X | G23: Colombia | H23: Choc√≥ | I23: 5.5781014 | J23: -77.502601 | K23: 42029 | L23: obsr399671 | M23: 0 | N23: URN:CornellLabOfOrnithology:EBIRD:OBS294630855
A24: Melanerpes pucherani | B24: 10668 | C24: species | D24: Black-cheeked Woodpecker | F24: 1 | G24: Colombia | H24: Choc√≥ | I24: 5.570735 | J24: -77.497034 | K24: 44762 | L24: obsr436508 | M24: 0 | N24: URN:CornellLabOfOrnithology:EBIRD:OBS1498853134 | O24: Manacus2022_
A25: Melanerpes pucherani | B25: 10668 | C25: species | D25: Black-cheeked Woodpecker | F25: 1 | G25: Colombia | H25: Choc√≥ | I25: 5.570735 | J25: -77.497034 | K25: 44762 | L25: obsr803013 | M25: 0 | N25: URN:CornellLabOfOrnithology:EBIRD:OBS1485279857
A26: Melanerpes pucherani | B26: 10668 | C26: species | D26: Black-cheeked Woodpecker | F26: 1 | G26: Colombia | H26: Choc√≥ | I26: 5.5712682 | J26: -77.501856 | K26: 44761 | L26: obsr436508 | M26: 1 | N26: URN:CornellLabOfOrnithology:EBIRD:OBS1498845107 | O26: Manacus2022_
A27: Melanerpes pucherani | B27: 10668 | C27: species | D27: Black-cheeked Woodpecker | F27: 1 | G27: Colombia | H27: Choc√≥ | I27: 5.5712682 | J27: -77.501856 | K27: 44761 | L27: obsr803013 | M27: 1 | N27: URN:CornellLabOfOrnithology:EBIRD:OBS1485273563
A28: Melanerpes pucherani | B28: 10668 | C28: species | D28: Black-cheeked Woodpecker | F28: 1 | G28: Colombia | H28: Choc√≥ | I28: 5.572016 | J28: -77.498527 | K28: 44761 | L28: obsr169881 | M28: 0 | N28: URN:CornellLabOfOrnithology:EBIRD:OBS1482382049 | O28: Manacus2022_Manacus expedition LSU-Humboldt Institute 2022. With Armancio as guide, we started at the El Amargal clearing then walked the Camino hasta Cuchilla de Arus√≠. Ending at clearing near the cuchilla (ridgetop) where we ate breakfast and hung out for a while. Good lighting and open views there for some canopy birds.
A29: Melanerpes pucherani | B29: 10668 | C29: species | D29: Black-cheeked Woodpecker | F29: 2 | G29: Colombia | H29: Choc√≥ | I29: 5.5729971 | J29: -77.498555 | K29: 44762 | L29: obsr792981 | M29: 0 | N29: URN:CornellLabOfOrnithology:EBIRD:OBS1484893428
A30: Melanerpes pucherani | B30: 10668 | C30: species | D30: Black-cheeked Woodpecker | F30: 2 | G30: Colombia | H30: Choc√≥ | I30: 5.573303 | J30: -77.501771 | K30: 44762 | L30: obsr169881 | M30: 0 | N30: URN:CornellLabOfOrnithology:EBIRD:OBS1505744129 | O30: Manacus2022_ Really nice flock right at the El Amargal clearing! And a bonus Brown Booby flyby.
A31: Melanerpes pucherani | B31: 10668 | C31: species | D31: Black-cheeked Woodpecker | F31: 2 | G31: Colombia | H31: Choc√≥ | I31: 5.573303 | J31: -77.501771 | K31: 44762 | L31: obsr792981 | M31: 0 | N31: URN:CornellLabOfOrnithology:EBIRD:OBS1484890932
A32: Melanerpes pucherani | B32: 10668 | C32: species | D32: Black-cheeked Woodpecker | F32: 2 | G32: Colombia | H32: Choc√≥ | I32: 5.573303 | J32: -77.501771 | K32: 44762 | L32: obsr803013 | M32: 0 | N32: URN:CornellLabOfOrnithology:EBIRD:OBS1485242232
A33: Melanerpes pucherani | B33: 10668 | C33: species | D33: Black-cheeked Woodpecker | F33: X | G33: Colombia | H33: Choc√≥ | I33: 5.5781014 | J33: -77.502601 | K33: 42029 | L33: obsr399671 | M33: 0 | N33: URN:CornellLabOfOrnithology:EBIRD:OBS294630830
A34: Crypturellus kerriae | B34: 110 | C34: species | D34: Choco Tinamou | F34: X | G34: Colombia | H34: Choc√≥ | I34: 5.5729759 | J34: -77.502419 | K34: 44622 | L34: obsr161341 | M34: 0 | N34: URN:CornellLabOfOrnithology:EBIRD:OBS1360123126 | O34: Birds seen/heard during March 2 ‚Äì 6, 2002 at El Amargal. Birding was not the primary activity in this visit. Lots of rain and cloudy days.
A35: Colaptes punctigula | B35: 11356 | C35: species | D35: Spot-breasted Woodpecker | F35: X | G35: Colombia | H35: Choc√≥ | I35: 5.5729759 | J35: -77.502419 | K35: 44622 | L35: obsr161341 | M35: 0 | N35: URN:CornellLabOfOrnithology:EBIRD:OBS1360123135 | O35: Birds seen/heard during March 2 ‚Äì 6, 2002 at El Amargal. Birding was not the primary activity in this visit. Lots of rain and cloudy days.
A36: Ibycter americanus | B36: 11425 | C36: species | D36: Red-throated Caracara | F36: X | G36: Colombia | H36: Choc√≥ | I36: 5.5729759 | J36: -77.502419 | K36: 44622 | L36: obsr161341 | M36: 0 | N36: URN:CornellLabOfOrnithology:EBIRD:OBS1360120810 | O36: Birds seen/heard during March 2 ‚Äì 6, 2002 at El Amargal. Birding was not the primary activity in this visit. Lots of rain and cloudy days.
A37: Falco peregrinus | B37: 11575 | C37: species | D37: Peregrine Falcon | F37: X | G37: Colombia | H37: Choc√≥ | I37: 5.5781014 | J37: -77.502601 | K37: 42029 | L37: obsr399671 | M37: 0 | N37: URN:CornellLabOfOrnithology:EBIRD:OBS294630827
A38: Pyrilia pulchra | B38: 12303 | C38: species | D38: Rose-faced Parrot | F38: 2 | G38: Colombia | H38: Choc√≥ | I38: 5.570735 | J38: -77.497034 | K38: 44762 | L38: obsr436508 | M38: 0 | N38: URN:CornellLabOfOrnithology:EBIRD:OBS1498853142 | O38: Manacus2022_
A39: Pyrilia pulchra | B39: 12303 | C39: species | D39: Rose-faced Parrot | F39: 2 | G39: Colombia | H39: Choc√≥ | I39: 5.570735 | J39: -77.497034 | K39: 44762 | L39: obsr803013 | M39: 0 | N39: URN:CornellLabOfOrnithology:EBIRD:OBS1485279865
A40: Pyrilia pyrilia | B40: 12304 | C40: species | D40: Saffron-headed Parrot | F40: X | G40: Colombia | H40: Choc√≥ | I40: 5.5729759 | J40: -77.502419 | K40: 44622 | L40: obsr161341 | M40: 0 | N40: URN:CornellLabOfOrnithology:EBIRD:OBS1360123137 | O40: Birds seen/heard during March 2 ‚Äì 6, 2002 at El Amargal. Birding was not the primary activity in this visit. Lots of rain and cloudy days.
...
